<?xml version="1.0" encoding="utf-8"?>
<!-- This URDF was automatically created by SolidWorks to URDF Exporter! Originally created by Stephen Brawner (brawner@gmail.com) 
     Commit Version: 1.6.0-4-g7f85cfe  Build Version: 1.6.7995.38578
     For more information, please see http://wiki.ros.org/sw_urdf_exporter -->
<robot name="Insect_Watcher" xmlns:xacro="http://ros.org/wiki/xacro">
  <link
    name="base_link">
    <inertial>
      <origin
        xyz="-0.00086422 -1.1102E-16 0.02434"
        rpy="0 0 0" />
      <mass
        value="15.038" />
      <inertia
        ixx="0.12715"
        ixy="-8.7269E-18"
        ixz="0.0020477"
        iyy="0.12272"
        iyz="1.2118E-18"
        izz="0.24325" />
    </inertial>
    <visual>
      <origin
        xyz="0 0 0"
        rpy="0 0 0" />
      <geometry>
        <mesh
          filename="package://Insect_Watcher/meshes/base_link.STL" />
      </geometry>
      <material
        name="">
        <color
          rgba="0.89804 0.91765 0.92941 1" />
      </material>
    </visual>
    <collision>
      <origin
        xyz="0 0 0"
        rpy="0 0 0" />
      <geometry>
        <mesh
          filename="package://Insect_Watcher/meshes/base_link.STL" />
      </geometry>
    </collision>
  </link>
  <link
    name="xlider_link">
    <inertial>
      <origin
        xyz="0.016 0.024695 -0.0075261"
        rpy="0 0 0" />
      <mass
        value="1.0009" />
      <inertia
        ixx="0.0047234"
        ixy="-5.9699E-18"
        ixz="3.7785E-20"
        iyy="0.00010039"
        iyz="2.4328E-05"
        izz="0.0047657" />
    </inertial>
    <visual>
      <origin
        xyz="0 0 0"
        rpy="0 0 0" />
      <geometry>
        <mesh
          filename="package://Insect_Watcher/meshes/xlider_link.STL" />
      </geometry>
      <material
        name="">
        <color
          rgba="0.52941 0.54902 0.54902 1" />
      </material>
    </visual>
    <collision>
      <origin
        xyz="0 0 0"
        rpy="0 0 0" />
      <geometry>
        <mesh
          filename="package://Insect_Watcher/meshes/xlider_link.STL" />
      </geometry>
    </collision>
  </link>
  <joint
    name="xslider_joint"
    type="prismatic">
    <origin
      xyz="-0.123 -0.015 0.2549"
      rpy="0 0 0" />
    <parent
      link="base_link" />
    <child
      link="xlider_link" />
    <axis
      xyz="1 0 0" />
    <limit
      lower="0"
      upper="0.203"
      effort="30"
      velocity="0.2" />
  </joint>
  <link
    name="yslider_link">
    <inertial>
      <origin
        xyz="0.015 0.016 0.0070462"
        rpy="0 0 0" />
      <mass
        value="0.095569" />
      <inertia
        ixx="9.7906E-06"
        ixy="-3.0698E-21"
        ixz="-2.2036E-22"
        iyy="9.2937E-06"
        iyz="-3.7386E-22"
        izz="1.5746E-05" />
    </inertial>
    <visual>
      <origin
        xyz="0 0 0"
        rpy="0 0 0" />
      <geometry>
        <mesh
          filename="package://Insect_Watcher/meshes/yslider_link.STL" />
      </geometry>
      <material
        name="">
        <color
          rgba="0.52941 0.54902 0.54902 1" />
      </material>
    </visual>
    <collision>
      <origin
        xyz="0 0 0"
        rpy="0 0 0" />
      <geometry>
        <mesh
          filename="package://Insect_Watcher/meshes/yslider_link.STL" />
      </geometry>
    </collision>
  </link>
  <joint
    name="yslider_joint"
    type="prismatic">
    <origin
      xyz="0.001 -0.1025 -0.027"
      rpy="0 0 0" />
    <parent
      link="xlider_link" />
    <child
      link="yslider_link" />
    <axis
      xyz="0 1 0" />
    <limit
      lower="0"
      upper="0.203"
      effort="30"
      velocity="0.2" />
  </joint>
  <link
    name="camera_link">
    <inertial>
      <origin
        xyz="-0.0082083 5.5511E-17 0"
        rpy="0 0 0" />
      <mass
        value="0.0023009" />
      <inertia
        ixx="9.2019E-08"
        ixy="4.8185E-24"
        ixz="-2.1244E-23"
        iyy="9.5904E-08"
        iyz="-1.8189E-24"
        izz="9.3405E-08" />
    </inertial>
    <visual>
      <origin
        xyz="0 0 0"
        rpy="0 0 0" />
      <geometry>
        <mesh
          filename="package://Insect_Watcher/meshes/camera_link.STL" />
      </geometry>
      <material
        name="">
        <color
          rgba="0.79216 0.81961 0.93333 1" />
      </material>
    </visual>
    <collision>
      <origin
        xyz="0 0 0"
        rpy="0 0 0" />
      <geometry>
        <mesh
          filename="package://Insect_Watcher/meshes/camera_link.STL" />
      </geometry>
    </collision>
  </link>
  <joint
    name="camera_joint"
    type="fixed">
    <origin
      xyz="0.015 0.016 -0.014"
      rpy="0 1.5708 0" />
    <parent
      link="yslider_link" />
    <child
      link="camera_link" />
    <axis
      xyz="0 0 0" />
  </joint>
</robot>